(djangopy3Env) C:\Users\Admin\Desktop\python_stack\django\django_intro\single_model_orm>manage.py migrate
Operations to perform:
  Apply all migrations: admin, auth, contenttypes, sessions, users_app
Running migrations:
  Applying contenttypes.0001_initial... OK
  Applying auth.0001_initial... OK
  Applying admin.0001_initial... OK
  Applying admin.0002_logentry_remove_auto_add... OK
  Applying admin.0003_logentry_add_action_flag_choices... OK
  Applying contenttypes.0002_remove_content_type_name... OK
  Applying auth.0002_alter_permission_name_max_length... OK
  Applying auth.0003_alter_user_email_max_length... OK
  Applying auth.0004_alter_user_username_opts... OK
  Applying auth.0005_alter_user_last_login_null... OK
  Applying auth.0006_require_contenttypes_0002... OK
  Applying auth.0007_alter_validators_add_error_messages... OK
  Applying auth.0008_alter_user_username_max_length... OK
  Applying auth.0009_alter_user_last_name_max_length... OK
  Applying auth.0010_alter_group_name_max_length... OK
  Applying auth.0011_update_proxy_permissions... OK
  Applying sessions.0001_initial... OK
  Applying users_app.0001_initial... OK

(djangopy3Env) C:\Users\Admin\Desktop\python_stack\django\django_intro\single_model_orm>python manage.py shell
Python 3.9.0 (tags/v3.9.0:9cf6752, Oct  5 2020, 15:34:40) [MSC v.1927 64 bit (AMD64)] on win32
Type "help", "copyright", "credits" or "license" for more information.
(InteractiveConsole)
>>> from users_app.models import User
>>> User.objectts.all()
Traceback (most recent call last):
  File "<console>", line 1, in <module>
AttributeError: type object 'User' has no attribute 'objectts'
>>> User.objects.create(first_name = "mario", last_name = "bartolo", email_address = "aewas@yahoo.com", age =
...
  File "<console>", line 1

    ^
SyntaxError: expression cannot contain assignment, perhaps you meant "=="?
>>>
>>>
>>> User.objects.all()
<QuerySet []>
>>> user.objects.create(first_name = "mario", last_name = "bartolo", email_address = "dsaer@yahoo.com", age = 21)
Traceback (most recent call last):
  File "<console>", line 1, in <module>
NameError: name 'user' is not defined
>>> User.objects.create(first_name = "mario", last_name = "bartolo", email_address = "ripaol@aim.com", age = 21)
<User: User object (1)>
>>> User.objects.all()
<QuerySet [<User: User object (1)>]>
>>> Movie.objects.first()
Traceback (most recent call last):
  File "<console>", line 1, in <module>
NameError: name 'Movie' is not defined
>>> User.objects.first()
<User: User object (1)>
>>> User.object.first().__dict__
Traceback (most recent call last):
  File "<console>", line 1, in <module>
AttributeError: type object 'User' has no attribute 'object'
>>> User.objects.first().__dict__
{'_state': <django.db.models.base.ModelState object at 0x000002EEC7BC6250>, 'id': 1, 'first_name': 'mario', 'last_name': 'bartolo', 'email_address': 'ripaol@aim.com', 'age': 21, 'created_at': datetime.datetime(2020, 12, 14, 21, 1, 8, 409866, tzinfo=<UTC>), 'updated_at': datetime.datetime(2020, 12, 14, 21, 1, 8, 409866, tzinfo=<UTC>)}
>>> User.objects.create(first_name= "joe", last_name = "hall", email_address = "saerea@gmail.com", age = 40)
<User: User object (2)>
>>> User.object.create(first_name = "gucci", last_name = "man", email_address = "yaaaaaa@aol.com", age = 23)
Traceback (most recent call last):
  File "<console>", line 1, in <module>
AttributeError: type object 'User' has no attribute 'object'
>>> User,objects.create(first_name = "gucci", last_name = "mane", email_address = "yeeesssir@aol.com", age = 23)
Traceback (most recent call last):
  File "<console>", line 1, in <module>
NameError: name 'objects' is not defined
>>> User.objects.create(first_name = "gucci", last_name= "mane", email_address = "yesssiirr@aol.com", age = 23)
<User: User object (3)>
>>> User.objects.all()
<QuerySet [<User: User object (1)>, <User: User object (2)>, <User: User object (3)>]>
>>> User.objects.first()
<User: User object (1)>
>>> User.objects.last()
<User: User object (3)>
>>> User_to_update = User.objects.get(id=3)
>>> User_to_update.last_name = "pancakes"
>>> user.objects.all()
Traceback (most recent call last):
  File "<console>", line 1, in <module>
NameError: name 'user' is not defined
>>> User.objects.all()
<QuerySet [<User: User object (1)>, <User: User object (2)>, <User: User object (3)>]>
>>> User2.save()
Traceback (most recent call last):
  File "<console>", line 1, in <module>
NameError: name 'User2' is not defined
>>> User_to_update.save()
>>> User_object(3).save()
Traceback (most recent call last):
  File "<console>", line 1, in <module>
NameError: name 'User_object' is not defined
>>> User(3).save()
Traceback (most recent call last):
  File "C:\Users\Admin\Desktop\python_stack\my_environments\djangopy3Env\lib\site-packages\django\db\backends\utils.py", line 84, in _execute
    return self.cursor.execute(sql, params)
  File "C:\Users\Admin\Desktop\python_stack\my_environments\djangopy3Env\lib\site-packages\django\db\backends\sqlite3\base.py", line 383, in execute
    return Database.Cursor.execute(self, query, params)
sqlite3.IntegrityError: NOT NULL constraint failed: users_app_user.age

The above exception was the direct cause of the following exception:

Traceback (most recent call last):
  File "<console>", line 1, in <module>
  File "C:\Users\Admin\Desktop\python_stack\my_environments\djangopy3Env\lib\site-packages\django\db\models\base.py", line 740, in save
    self.save_base(using=using, force_insert=force_insert,
  File "C:\Users\Admin\Desktop\python_stack\my_environments\djangopy3Env\lib\site-packages\django\db\models\base.py", line 777, in save_base
    updated = self._save_table(
  File "C:\Users\Admin\Desktop\python_stack\my_environments\djangopy3Env\lib\site-packages\django\db\models\base.py", line 850, in _save_table
    updated = self._do_update(base_qs, using, pk_val, values, update_fields,
  File "C:\Users\Admin\Desktop\python_stack\my_environments\djangopy3Env\lib\site-packages\django\db\models\base.py", line 900, in _do_update
    return filtered._update(values) > 0
  File "C:\Users\Admin\Desktop\python_stack\my_environments\djangopy3Env\lib\site-packages\django\db\models\query.py", line 760, in _update
    return query.get_compiler(self.db).execute_sql(CURSOR)
  File "C:\Users\Admin\Desktop\python_stack\my_environments\djangopy3Env\lib\site-packages\django\db\models\sql\compiler.py", line 1429, in execute_sql
    cursor = super().execute_sql(result_type)
  File "C:\Users\Admin\Desktop\python_stack\my_environments\djangopy3Env\lib\site-packages\django\db\models\sql\compiler.py", line 1100, in execute_sql
    cursor.execute(sql, params)
  File "C:\Users\Admin\Desktop\python_stack\my_environments\djangopy3Env\lib\site-packages\django\db\backends\utils.py", line 99, in execute
    return super().execute(sql, params)
  File "C:\Users\Admin\Desktop\python_stack\my_environments\djangopy3Env\lib\site-packages\django\db\backends\utils.py", line 67, in execute
    return self._execute_with_wrappers(sql, params, many=False, executor=self._execute)
  File "C:\Users\Admin\Desktop\python_stack\my_environments\djangopy3Env\lib\site-packages\django\db\backends\utils.py", line 76, in _execute_with_wrappers
    return executor(sql, params, many, context)
  File "C:\Users\Admin\Desktop\python_stack\my_environments\djangopy3Env\lib\site-packages\django\db\backends\utils.py", line 84, in _execute
    return self.cursor.execute(sql, params)
  File "C:\Users\Admin\Desktop\python_stack\my_environments\djangopy3Env\lib\site-packages\django\db\utils.py", line 89, in __exit__
    raise dj_exc_value.with_traceback(traceback) from exc_value
  File "C:\Users\Admin\Desktop\python_stack\my_environments\djangopy3Env\lib\site-packages\django\db\backends\utils.py", line 84, in _execute
    return self.cursor.execute(sql, params)
  File "C:\Users\Admin\Desktop\python_stack\my_environments\djangopy3Env\lib\site-packages\django\db\backends\sqlite3\base.py", line 383, in execute
    return Database.Cursor.execute(self, query, params)
django.db.utils.IntegrityError: NOT NULL constraint failed: users_app_user.age
>>> User.objects.dict()
Traceback (most recent call last):
  File "<console>", line 1, in <module>
AttributeError: 'Manager' object has no attribute 'dict'
>>> User.objects.last()dict
  File "<console>", line 1
    User.objects.last()dict
                       ^
SyntaxError: invalid syntax
>>> User.objects.last().__dict__
{'_state': <django.db.models.base.ModelState object at 0x000002EEC7BC69D0>, 'id': 3, 'first_name': 'gucci', 'last_name': 'pancakes', 'email_address': 'yesssiirr@aol.com', 'age': 23, 'created_at': datetime.datetime(2020, 12, 14, 22, 27, 22, 838987, tzinfo=<UTC>), 'updated_at': datetime.datetime(2020, 12, 14, 22, 27, 22, 838987, tzinfo=<UTC>)}
>>> User_to_delete = User.objects.get(id=2)
>>> User_to_delete.delete()
(1, {'users_app.User': 1})
>>> User.objects.first().__dict__
{'_state': <django.db.models.base.ModelState object at 0x000002EEC7BC62E0>, 'id': 1, 'first_name': 'mario', 'last_name': 'bartolo', 'email_address': 'ripaol@aim.com', 'age': 21, 'created_at': datetime.datetime(2020, 12, 14, 21, 1, 8, 409866, tzinfo=<UTC>), 'updated_at': datetime.datetime(2020, 12, 14, 21, 1, 8, 409866, tzinfo=<UTC>)}
>>> User.objects.all().__dict__
{'model': <class 'users_app.models.User'>, '_db': None, '_hints': {}, 'query': <django.db.models.sql.query.Query object at 0x000002EEC7B89F40>, '_result_cache': None, '_sticky_filter': False, '_for_write': False, '_prefetch_related_lookups': (), '_prefetch_done': False, '_known_related_objects': {}, '_iterable_class': <class 'django.db.models.query.ModelIterable'>, '_fields': None}
>>> User.objects.all()
<QuerySet [<User: User object (1)>, <User: User object (3)>]>
>>> User = user.objects.filter('last_name')
Traceback (most recent call last):
  File "<console>", line 1, in <module>
NameError: name 'user' is not defined
>>> User = User.objects.filter('last_name')
Traceback (most recent call last):
  File "<console>", line 1, in <module>
  File "C:\Users\Admin\Desktop\python_stack\my_environments\djangopy3Env\lib\site-packages\django\db\models\manager.py", line 82, in manager_method
    return getattr(self.get_queryset(), name)(*args, **kwargs)
  File "C:\Users\Admin\Desktop\python_stack\my_environments\djangopy3Env\lib\site-packages\django\db\models\query.py", line 892, in filter
    return self._filter_or_exclude(False, *args, **kwargs)
  File "C:\Users\Admin\Desktop\python_stack\my_environments\djangopy3Env\lib\site-packages\django\db\models\query.py", line 910, in _filter_or_exclude
    clone.query.add_q(Q(*args, **kwargs))
  File "C:\Users\Admin\Desktop\python_stack\my_environments\djangopy3Env\lib\site-packages\django\db\models\sql\query.py", line 1290, in add_q
    clause, _ = self._add_q(q_object, self.used_aliases)
  File "C:\Users\Admin\Desktop\python_stack\my_environments\djangopy3Env\lib\site-packages\django\db\models\sql\query.py", line 1315, in _add_q
    child_clause, needed_inner = self.build_filter(
  File "C:\Users\Admin\Desktop\python_stack\my_environments\djangopy3Env\lib\site-packages\django\db\models\sql\query.py", line 1187, in build_filter
    arg, value = filter_expr
ValueError: too many values to unpack (expected 2)
>>> User = User.objects.filter(first_name)
Traceback (most recent call last):
  File "<console>", line 1, in <module>
NameError: name 'first_name' is not defined
>>> User.objects.get(field1 = "first_name")
Traceback (most recent call last):
  File "<console>", line 1, in <module>
  File "C:\Users\Admin\Desktop\python_stack\my_environments\djangopy3Env\lib\site-packages\django\db\models\manager.py", line 82, in manager_method
    return getattr(self.get_queryset(), name)(*args, **kwargs)
  File "C:\Users\Admin\Desktop\python_stack\my_environments\djangopy3Env\lib\site-packages\django\db\models\query.py", line 399, in get
    clone = self.filter(*args, **kwargs)
  File "C:\Users\Admin\Desktop\python_stack\my_environments\djangopy3Env\lib\site-packages\django\db\models\query.py", line 892, in filter
    return self._filter_or_exclude(False, *args, **kwargs)
  File "C:\Users\Admin\Desktop\python_stack\my_environments\djangopy3Env\lib\site-packages\django\db\models\query.py", line 910, in _filter_or_exclude
    clone.query.add_q(Q(*args, **kwargs))
  File "C:\Users\Admin\Desktop\python_stack\my_environments\djangopy3Env\lib\site-packages\django\db\models\sql\query.py", line 1290, in add_q
    clause, _ = self._add_q(q_object, self.used_aliases)
  File "C:\Users\Admin\Desktop\python_stack\my_environments\djangopy3Env\lib\site-packages\django\db\models\sql\query.py", line 1315, in _add_q
    child_clause, needed_inner = self.build_filter(
  File "C:\Users\Admin\Desktop\python_stack\my_environments\djangopy3Env\lib\site-packages\django\db\models\sql\query.py", line 1190, in build_filter
    lookups, parts, reffed_expression = self.solve_lookup_type(arg)
  File "C:\Users\Admin\Desktop\python_stack\my_environments\djangopy3Env\lib\site-packages\django\db\models\sql\query.py", line 1049, in solve_lookup_type
    _, field, _, lookup_parts = self.names_to_path(lookup_splitted, self.get_meta())
  File "C:\Users\Admin\Desktop\python_stack\my_environments\djangopy3Env\lib\site-packages\django\db\models\sql\query.py", line 1419, in names_to_path
    raise FieldError("Cannot resolve keyword '%s' into field. "
django.core.exceptions.FieldError: Cannot resolve keyword 'field1' into field. Choices are: age, created_at, email_address, first_name, id, last_name, updated_at
>>> User = User.objects.get(id = 1)
>>> User.first_name
'mario'
>>> User.objects.all()
Traceback (most recent call last):
  File "<console>", line 1, in <module>
  File "C:\Users\Admin\Desktop\python_stack\my_environments\djangopy3Env\lib\site-packages\django\db\models\manager.py", line 176, in __get__
    raise AttributeError("Manager isn't accessible via %s instances" % cls.__name__)
AttributeError: Manager isn't accessible via User instances
>>> (exit)
Use exit() or Ctrl-Z plus Return to exit
>>> exit()

(djangopy3Env) C:\Users\Admin\Desktop\python_stack\django\django_intro\single_model_orm>python manage.py shell
Python 3.9.0 (tags/v3.9.0:9cf6752, Oct  5 2020, 15:34:40) [MSC v.1927 64 bit (AMD64)] on win32
Type "help", "copyright", "credits" or "license" for more information.
(InteractiveConsole)
>>> from users_app.models import User
>>> user = User.objects.get(id = 1)
>>> user.firstname
Traceback (most recent call last):
  File "<console>", line 1, in <module>
AttributeError: 'User' object has no attribute 'firstname'
>>> user.first_name
'mario'
>>> User.objects.all()
<QuerySet [<User: User object (1)>, <User: User object (3)>]>
>>> user.objects.all().order_by('first_name')
Traceback (most recent call last):
  File "<console>", line 1, in <module>
  File "C:\Users\Admin\Desktop\python_stack\my_environments\djangopy3Env\lib\site-packages\django\db\models\manager.py", line 176, in __get__
    raise AttributeError("Manager isn't accessible via %s instances" % cls.__name__)
AttributeError: Manager isn't accessible via User instances
>>> User.object.all().order_by('first_name')
Traceback (most recent call last):
  File "<console>", line 1, in <module>
AttributeError: type object 'User' has no attribute 'object'
>>> User.objects.all().order_by('first_name')
<QuerySet [<User: User object (3)>, <User: User object (1)>]>